<?xml version="1.0" ?>
<robot
  name="Faraday">

  <link name="world" />

  <joint name="world_to_base_link" type="fixed">
    <parent link="world"/>
    <child link="base_link"/>
    <origin xyz="0 -0.01553 0.604" rpy="3.141592654 0 0"/>
  </joint>

  <link
    name="base_link">
    <inertial>
      <origin
        xyz="-0.0065986 -0.032962 0.49853"
        rpy="0 0 0" />
      <mass
        value="12.551" />
      <inertia
        ixx="5.8372"
        ixy="-0.020361"
        ixz="-0.034318"
        iyy="6.0197"
        iyz="0.0069877"
        izz="0.44893" />
    </inertial>
    <visual>
      <origin
        xyz="0 0 0"
        rpy="0 0 0" />
      <geometry>
        <mesh
          filename="package://faraday_support/meshes/base_link.STL" />
      </geometry>
      <material
        name="">
        <color
          rgba="1 0.6 0 1" />
      </material>
    </visual>
    <collision>
      <origin
        xyz="0 0 0"
        rpy="0 0 0" />
      <geometry>
        <mesh
          filename="package://faraday_support/meshes/base_link.STL" />
      </geometry>
    </collision>
  </link>

<!-- !!!!!!!!!!!!!!!!!!!!!!!!!!!the limb1!!!!!!!!!!!!!!!!!!!!!!!!!!! -->
  <joint
    name="limb1_link1_joint"
    type="prismatic">
    <origin
      xyz="256.999999E-03 128.293085E-03 147.144575E-03"
      rpy="0 0 -0.523598775598299" />
    <parent
      link="base_link" />
    <child
      link="limb1_link1" />
    <axis
      xyz="0 0 1" />
    <limit
      lower="-116.3446E-03"
      upper="112.0554E-03"
      effort="0"
      velocity="0" />
  </joint>

  <link
    name="limb1_link1">
    <inertial>
      <origin
        xyz="-0.030335230E-03 -5.384161855E-03 0.114498889E-03"
        rpy="0 0 0" />
      <mass
        value="0.317239094" />
      <inertia
        ixx="122.332939099E-06"
        ixy="0.005927642E-06"
        ixz="-0.325801595E-06"
        iyy="127.383902955E-06"
        iyz="-0.022373613E-06"
        izz="61.480921161E-06" />
    </inertial>
    <visual>
      <origin
        xyz="0 0 0"
        rpy="0 0 0" />
      <geometry>
        <mesh
          filename="package://faraday_support/meshes/limb1_link1.STL" />
      </geometry>
      <material
        name="">
        <color
          rgba="0.79216 0.81961 0.93333 1" />
      </material>
    </visual>
    <collision>
      <origin
        xyz="0 0 0"
        rpy="0 0 0" />
      <geometry>
        <mesh
          filename="package://faraday_support/meshes/limb1_link1.STL" />
      </geometry>
    </collision>
  </link>

  <joint
    name="limb1_link2_joint"
    type="continuous">
    <origin
      xyz="0 -58.0E-03 0"
      rpy="-1.570796326794897 -0.896668139199843 3.141592653589793" />
    <parent
      link="limb1_link1" />
    <child
      link="limb1_link2" />
    <axis
      xyz="0 0 1" />
  </joint>

  <link
    name="limb1_link2">
    <inertial>
      <origin
        xyz="0 0 -7.175692738E-03"
        rpy="0 0 0" />
      <mass
        value="0.063268400" />
      <inertia
        ixx="20.615640235E-06"
        ixy="0"
        ixz="0"
        iyy="10.070601654E-06"
        iyz="0"
        izz="15.963087509E-06" />
    </inertial>
    <visual>
      <origin
        xyz="0 0 0"
        rpy="0 0 0" />
      <geometry>
        <mesh
          filename="package://faraday_support/meshes/limb1_link2.STL" />
      </geometry>
      <material
        name="">
        <color
          rgba="1 0.6 0 1" />
      </material>
    </visual>
    <collision>
      <origin
        xyz="0 0 0"
        rpy="0 0 0" />
      <geometry>
        <mesh
          filename="package://faraday_support/meshes/limb1_link2.STL" />
      </geometry>
    </collision>
  </link>

  <joint
    name="limb1_link3_joint"
    type="revolute">
    <origin
      xyz="0 0 0"
      rpy="-1.570796326794897 -1.011023857119764 3.141592653589793" />
    <parent
      link="limb1_link2" />
    <child
      link="limb1_link3" />
    <axis
      xyz="0 0 1" />
    <limit
      lower="-1.57"
      upper="1.57"
      effort="0"
      velocity="0" />
  </joint>

  <link
    name="limb1_link3">
    <inertial>
      <origin
        xyz="0 -101.508543691E-03 0"
        rpy="0 0 0" />
      <mass
        value="0.048981588" />
      <inertia
        ixx="283.193897053E-06"
        ixy="0"
        ixz="0"
        iyy="0.978504361E-06"
        iyz="0"
        izz="282.792129790E-06" />
    </inertial>
    <visual>
      <origin
        xyz="0 0 0"
        rpy="0 0 0" />
      <geometry>
        <mesh
          filename="package://faraday_support/meshes/limb1_link3.STL" />
      </geometry>
      <material
        name="">
        <color
          rgba="0.807843137254902 0.843137254901961 0.905882352941176 1" />
      </material>
    </visual>
    <collision>
      <origin
        xyz="0 0 0"
        rpy="0 0 0" />
      <geometry>
        <mesh
          filename="package://faraday_support/meshes/limb1_link3.STL" />
      </geometry>
    </collision>
  </link> 

  <joint
    name="limb1_link4_joint"
    type="continuous">
    <origin
      xyz="0 -246.0E-03 0"
      rpy="1.570796326794897 1.371521614119192 0" />
    <parent
      link="limb1_link3" />
    <child
      link="limb1_link4" />
    <axis
      xyz="0 0 1" />
  </joint>

  <link
    name="limb1_link4">
    <inertial>
      <origin
        xyz="0 0 -28.989992853E-03"
        rpy="0 0 0" />
      <mass
        value="0.043557642" />
      <inertia
        ixx="16.645965669E-06"
        ixy="0"
        ixz="0"
        iyy="16.244198406E-06"
        iyz="0"
        izz="2.976607171E-06" />
    </inertial>
    <visual>
      <origin
        xyz="0 0 0"
        rpy="0 0 0" />
      <geometry>
        <mesh
          filename="package://faraday_support/meshes/limb1_link4.STL" />
      </geometry>
      <material
        name="">
        <color
          rgba="0.807843137254902 0.843137254901961 0.905882352941176 1" />
      </material>
    </visual>
    <collision>
      <origin
        xyz="0 0 0"
        rpy="0 0 0" />
      <geometry>
        <mesh
          filename="package://faraday_support/meshes/limb1_link4.STL" />
      </geometry>
    </collision>
  </link>

  <joint
    name="limb1_link5_joint"
    type="revolute">
    <origin
      xyz="0 0 0"
      rpy="1.570796326794897 0.761825746520013 0" />
    <parent
      link="limb1_link4" />
    <child
      link="limb1_link5" />
    <axis
      xyz="0 0 1" />
    <limit
      lower="-1.57"
      upper="3.14"
      effort="0"
      velocity="0" />
  </joint>

  <link
    name="limb1_link5">
    <inertial>
      <origin
        xyz="0 5.927141064E-03 0"
        rpy="0 0 0" />
      <mass
        value="0.059458429" />
      <inertia
        ixx="18.846035620E-06"
        ixy="0"
        ixz="0"
        iyy="15.857290969E-06"
        iyz="0"
        izz="8.300960836E-06" />
    </inertial>
    <visual>
      <origin
        xyz="0 0 0"
        rpy="0 0 0" />
      <geometry>
        <mesh
          filename="package://faraday_support/meshes/limb1_link5.STL" />
      </geometry>
      <material
        name="">
        <color
          rgba="1 0.6 0 1" />
      </material>
    </visual>
    <collision>
      <origin
        xyz="0 0 0"
        rpy="0 0 0" />
      <geometry>
        <mesh
          filename="package://faraday_support/meshes/limb1_link5.STL" />
      </geometry>
    </collision>
  </link>


<!-- !!!!!!!!!!!!!!!!!!!!!!!!!!!the limb2!!!!!!!!!!!!!!!!!!!!!!!!!!! -->
  <joint
    name="limb2_link1_joint"
    type="prismatic">
    <origin
      xyz="243.823085E-03 -172.53E-03 145.659457E-03"
      rpy="0 0 -2.094395102393196" />
    <parent
      link="base_link" />
    <child
      link="limb2_link1" />
    <axis
      xyz="0 0 1" />
    <limit
      lower="-114.8595E-03"
      upper="123.5405E-03"
      effort="0"
      velocity="0" />
  </joint>

  <link
    name="limb2_link1">
    <inertial>
      <origin
        xyz="-0.030335230E-03 -5.384161855E-03 0.114498889E-03"
        rpy="0 0 0" />
      <mass
        value="0.317239094" />
      <inertia
        ixx="122.332939099E-06"
        ixy="0.005927642E-06"
        ixz="-0.325801595E-06"
        iyy="127.383902955E-06"
        iyz="-0.022373613E-06"
        izz="61.480921161E-06" />
    </inertial>
    <visual>
      <origin
        xyz="0 0 0"
        rpy="0 0 0" />
      <geometry>
        <mesh
          filename="package://faraday_support/meshes/limb1_link1.STL" />
      </geometry>
      <material
        name="">
        <color
          rgba="0.79216 0.81961 0.93333 1" />
      </material>
    </visual>
    <collision>
      <origin
        xyz="0 0 0"
        rpy="0 0 0" />
      <geometry>
        <mesh
          filename="package://faraday_support/meshes/limb1_link1.STL" />
      </geometry>
    </collision>
  </link>

  <joint
    name="limb2_link2_joint"
    type="continuous">
    <origin
      xyz="0 -58.0E-03 0"
      rpy="-1.570796326794897 -1.410784540972056 3.141592653589793" />
    <parent
      link="limb2_link1" />
    <child
      link="limb2_link2" />
    <axis
      xyz="0 0 1" />
  </joint>

  <link
    name="limb2_link2">
    <inertial>
      <origin
        xyz="0 0 -7.175692738E-03"
        rpy="0 0 0" />
      <mass
        value="0.063268400" />
      <inertia
        ixx="20.615640235E-06"
        ixy="0"
        ixz="0"
        iyy="10.070601654E-06"
        iyz="0"
        izz="15.963087509E-06" />
    </inertial>
    <visual>
      <origin
        xyz="0 0 0"
        rpy="0 0 0" />
      <geometry>
        <mesh
          filename="package://faraday_support/meshes/limb1_link2.STL" />
      </geometry>
      <material
        name="">
        <color
          rgba="1 0.6 0 1" />
      </material>
    </visual>
    <collision>
      <origin
        xyz="0 0 0"
        rpy="0 0 0" />
      <geometry>
        <mesh
          filename="package://faraday_support/meshes/limb1_link2.STL" />
      </geometry>
    </collision>
  </link>

  <joint
    name="limb2_link3_joint"
    type="revolute">
    <origin
      xyz="0 0 0"
      rpy="-1.570796326794897 -0.743264169925054 3.141592653589793" />
    <parent
      link="limb2_link2" />
    <child
      link="limb2_link3" />
    <axis
      xyz="0 0 1" />
    <limit
      lower="-1.57"
      upper="1.57"
      effort="0"
      velocity="0" />
  </joint>

  <link
    name="limb2_link3">
    <inertial>
      <origin
        xyz="0 -101.508543691E-03 0"
        rpy="0 0 0" />
      <mass
        value="0.048981588" />
      <inertia
        ixx="283.193897053E-06"
        ixy="0"
        ixz="0"
        iyy="0.978504361E-06"
        iyz="0"
        izz="282.792129790E-06" />
    </inertial>
    <visual>
      <origin
        xyz="0 0 0"
        rpy="0 0 0" />
      <geometry>
        <mesh
          filename="package://faraday_support/meshes/limb1_link3.STL" />
      </geometry>
      <material
        name="">
        <color
          rgba="0.807843137254902 0.843137254901961 0.905882352941176 1" />
      </material>
    </visual>
    <collision>
      <origin
        xyz="0 0 0"
        rpy="0 0 0" />
      <geometry>
        <mesh
          filename="package://faraday_support/meshes/limb1_link3.STL" />
      </geometry>
    </collision>
  </link> 

  <joint
    name="limb2_link4_joint"
    type="continuous">
    <origin
      xyz="0 -246.0E-03 0"
      rpy="1.570796326794897 -0.653447781288173 0" />
    <parent
      link="limb2_link3" />
    <child
      link="limb2_link4" />
    <axis
      xyz="0 0 1" />
  </joint>

  <link
    name="limb2_link4">
    <inertial>
      <origin
        xyz="0 0 -28.989992853E-03"
        rpy="0 0 0" />
      <mass
        value="0.043557642" />
      <inertia
        ixx="16.645965669E-06"
        ixy="0"
        ixz="0"
        iyy="16.244198406E-06"
        iyz="0"
        izz="2.976607171E-06" />
    </inertial>
    <visual>
      <origin
        xyz="0 0 0"
        rpy="0 0 0" />
      <geometry>
        <mesh
          filename="package://faraday_support/meshes/limb1_link4.STL" />
      </geometry>
      <material
        name="">
        <color
          rgba="0.807843137254902 0.843137254901961 0.905882352941176 1" />
      </material>
    </visual>
    <collision>
      <origin
        xyz="0 0 0"
        rpy="0 0 0" />
      <geometry>
        <mesh
          filename="package://faraday_support/meshes/limb1_link4.STL" />
      </geometry>
    </collision>
  </link>

  <joint
    name="limb2_link5_joint"
    type="revolute">
    <origin
      xyz="0 0 0"
      rpy="1.570796326794897 0.947500853664178 0" />
    <parent
      link="limb2_link4" />
    <child
      link="limb2_link5" />
    <axis
      xyz="0 0 1" />
    <limit
      lower="-1.57"
      upper="3.14"
      effort="0"
      velocity="0" />
  </joint>

  <link
    name="limb2_link5">
    <inertial>
      <origin
        xyz="0 5.927141064E-03 0"
        rpy="0 0 0" />
      <mass
        value="0.059458429" />
      <inertia
        ixx="18.846035620E-06"
        ixy="0"
        ixz="0"
        iyy="15.857290969E-06"
        iyz="0"
        izz="8.300960836E-06" />
    </inertial>
    <visual>
      <origin
        xyz="0 0 0"
        rpy="0 0 0" />
      <geometry>
        <mesh
          filename="package://faraday_support/meshes/limb1_link5.STL" />
      </geometry>
      <material
        name="">
        <color
          rgba="1 0.6 0 1" />
      </material>
    </visual>
    <collision>
      <origin
        xyz="0 0 0"
        rpy="0 0 0" />
      <geometry>
        <mesh
          filename="package://faraday_support/meshes/limb1_link5.STL" />
      </geometry>
    </collision>
  </link>  


<!-- !!!!!!!!!!!!!!!!!!!!!!!!!!!the limb3!!!!!!!!!!!!!!!!!!!!!!!!!!! -->
  <joint
    name="limb3_link1_joint"
    type="prismatic">
    <origin
      xyz="-243.823085E-03 -172.53E-03 145.659457E-03"
      rpy="0 0 2.094395102393196" />
    <parent
      link="base_link" />
    <child
      link="limb3_link1" />
    <axis
      xyz="0 0 1" />
    <limit
      lower="-114.8595E-03"
      upper="123.5405E-03"
      effort="0"
      velocity="0" />
  </joint>

  <link
    name="limb3_link1">
    <inertial>
      <origin
        xyz="-0.030335230E-03 -5.384161855E-03 0.114498889E-03"
        rpy="0 0 0" />
      <mass
        value="0.317239094" />
      <inertia
        ixx="122.332939099E-06"
        ixy="0.005927642E-06"
        ixz="-0.325801595E-06"
        iyy="127.383902955E-06"
        iyz="-0.022373613E-06"
        izz="61.480921161E-06" />
    </inertial>
    <visual>
      <origin
        xyz="0 0 0"
        rpy="0 0 0" />
      <geometry>
        <mesh
          filename="package://faraday_support/meshes/limb1_link1.STL" />
      </geometry>
      <material
        name="">
        <color
          rgba="0.79216 0.81961 0.93333 1" />
      </material>
    </visual>
    <collision>
      <origin
        xyz="0 0 0"
        rpy="0 0 0" />
      <geometry>
        <mesh
          filename="package://faraday_support/meshes/limb1_link1.STL" />
      </geometry>
    </collision>
  </link>

  <joint
    name="limb3_link2_joint"
    type="continuous">
    <origin
      xyz="0 -58.0E-03 0"
      rpy="1.570796326794897 -1.410784540972056 0" />
    <parent
      link="limb3_link1" />
    <child
      link="limb3_link2" />
    <axis
      xyz="0 0 1" />
  </joint>

  <link
    name="limb3_link2">
    <inertial>
      <origin
        xyz="0 0 -7.175692738E-03"
        rpy="0 0 0" />
      <mass
        value="0.063268400" />
      <inertia
        ixx="20.615640235E-06"
        ixy="0"
        ixz="0"
        iyy="10.070601654E-06"
        iyz="0"
        izz="15.963087509E-06" />
    </inertial>
    <visual>
      <origin
        xyz="0 0 0"
        rpy="0 0 0" />
      <geometry>
        <mesh
          filename="package://faraday_support/meshes/limb1_link2.STL" />
      </geometry>
      <material
        name="">
        <color
          rgba="1 0.6 0 1" />
      </material>
    </visual>
    <collision>
      <origin
        xyz="0 0 0"
        rpy="0 0 0" />
      <geometry>
        <mesh
          filename="package://faraday_support/meshes/limb1_link2.STL" />
      </geometry>
    </collision>
  </link>

  <joint
    name="limb3_link3_joint"
    type="revolute">
    <origin
      xyz="0 0 0"
      rpy="-1.570796326794897 -0.743264169925054 3.141592653589793" />
    <parent
      link="limb3_link2" />
    <child
      link="limb3_link3" />
    <axis
      xyz="0 0 1" />
    <limit
      lower="-1.57"
      upper="1.57"
      effort="0"
      velocity="0" />
  </joint>

  <link
    name="limb3_link3">
    <inertial>
      <origin
        xyz="0 -101.508543691E-03 0"
        rpy="0 0 0" />
      <mass
        value="0.048981588" />
      <inertia
        ixx="283.193897053E-06"
        ixy="0"
        ixz="0"
        iyy="0.978504361E-06"
        iyz="0"
        izz="282.792129790E-06" />
    </inertial>
    <visual>
      <origin
        xyz="0 0 0"
        rpy="0 0 0" />
      <geometry>
        <mesh
          filename="package://faraday_support/meshes/limb1_link3.STL" />
      </geometry>
      <material
        name="">
        <color
          rgba="0.807843137254902 0.843137254901961 0.905882352941176 1" />
      </material>
    </visual>
    <collision>
      <origin
        xyz="0 0 0"
        rpy="0 0 0" />
      <geometry>
        <mesh
          filename="package://faraday_support/meshes/limb1_link3.STL" />
      </geometry>
    </collision>
  </link> 

  <joint
    name="limb3_link4_joint"
    type="continuous">
    <origin
      xyz="0 -246.0E-03 0"
      rpy="1.570796326794897 0.653447781288173 0" />
    <parent
      link="limb3_link3" />
    <child
      link="limb3_link4" />
    <axis
      xyz="0 0 1" />
  </joint>

  <link
    name="limb3_link4">
    <inertial>
      <origin
        xyz="0 0 -28.989992853E-03"
        rpy="0 0 0" />
      <mass
        value="0.043557642" />
      <inertia
        ixx="16.645965669E-06"
        ixy="0"
        ixz="0"
        iyy="16.244198406E-06"
        iyz="0"
        izz="2.976607171E-06" />
    </inertial>
    <visual>
      <origin
        xyz="0 0 0"
        rpy="0 0 0" />
      <geometry>
        <mesh
          filename="package://faraday_support/meshes/limb1_link4.STL" />
      </geometry>
      <material
        name="">
        <color
          rgba="0.807843137254902 0.843137254901961 0.905882352941176 1" />
      </material>
    </visual>
    <collision>
      <origin
        xyz="0 0 0"
        rpy="0 0 0" />
      <geometry>
        <mesh
          filename="package://faraday_support/meshes/limb1_link4.STL" />
      </geometry>
    </collision>
  </link>

  <joint
    name="limb3_link5_joint"
    type="revolute">
    <origin
      xyz="0 0 0"
      rpy="1.570796326794897 0.947500853664178 0" />
    <parent
      link="limb3_link4" />
    <child
      link="limb3_link5" />
    <axis
      xyz="0 0 1" />
    <limit
      lower="-1.57"
      upper="3.14"
      effort="0"
      velocity="0" />
  </joint>

  <link
    name="limb3_link5">
    <inertial>
      <origin
        xyz="0 5.927141064E-03 0"
        rpy="0 0 0" />
      <mass
        value="0.059458429" />
      <inertia
        ixx="18.846035620E-06"
        ixy="0"
        ixz="0"
        iyy="15.857290969E-06"
        iyz="0"
        izz="8.300960836E-06" />
    </inertial>
    <visual>
      <origin
        xyz="0 0 0"
        rpy="0 0 0" />
      <geometry>
        <mesh
          filename="package://faraday_support/meshes/limb1_link5.STL" />
      </geometry>
      <material
        name="">
        <color
          rgba="1 0.6 0 1" />
      </material>
    </visual>
    <collision>
      <origin
        xyz="0 0 0"
        rpy="0 0 0" />
      <geometry>
        <mesh
          filename="package://faraday_support/meshes/limb1_link5.STL" />
      </geometry>
    </collision>
  </link>


<!-- !!!!!!!!!!!!!!!!!!!!!!!!!!!the limb4!!!!!!!!!!!!!!!!!!!!!!!!!!! -->
  <joint
    name="limb4_link1_joint"
    type="prismatic">
    <origin
      xyz="-256.999999E-03 128.293085E-03 147.144575E-03"
      rpy="0 0 0.523598775598299" />
    <parent
      link="base_link" />
    <child
      link="limb4_link1" />
    <axis
      xyz="0 0 1" />
    <limit
      lower="-116.3446E-03"
      upper="112.0554E-03"
      effort="0"
      velocity="0" />
  </joint>

  <link
    name="limb4_link1">
    <inertial>
      <origin
        xyz="-0.030335230E-03 -5.384161855E-03 0.114498889E-03"
        rpy="0 0 0" />
      <mass
        value="0.317239094" />
      <inertia
        ixx="122.332939099E-06"
        ixy="0.005927642E-06"
        ixz="-0.325801595E-06"
        iyy="127.383902955E-06"
        iyz="-0.022373613E-06"
        izz="61.480921161E-06" />
    </inertial>
    <visual>
      <origin
        xyz="0 0 0"
        rpy="0 0 0" />
      <geometry>
        <mesh
          filename="package://faraday_support/meshes/limb1_link1.STL" />
      </geometry>
      <material
        name="">
        <color
          rgba="0.79216 0.81961 0.93333 1" />
      </material>
    </visual>
    <collision>
      <origin
        xyz="0 0 0"
        rpy="0 0 0" />
      <geometry>
        <mesh
          filename="package://faraday_support/meshes/limb1_link1.STL" />
      </geometry>
    </collision>
  </link>

  <joint
    name="limb4_link2_joint"
    type="continuous">
    <origin
      xyz="0 -58.0E-03 0"
      rpy="1.570796326794897 -0.896668139199843 0" />
    <parent
      link="limb4_link1" />
    <child
      link="limb4_link2" />
    <axis
      xyz="0 0 1" />
  </joint>

  <link
    name="limb4_link2">
    <inertial>
      <origin
        xyz="0 0 -7.175692738E-03"
        rpy="0 0 0" />
      <mass
        value="0.063268400" />
      <inertia
        ixx="20.615640235E-06"
        ixy="0"
        ixz="0"
        iyy="10.070601654E-06"
        iyz="0"
        izz="15.963087509E-06" />
    </inertial>
    <visual>
      <origin
        xyz="0 0 0"
        rpy="0 0 0" />
      <geometry>
        <mesh
          filename="package://faraday_support/meshes/limb1_link2.STL" />
      </geometry>
      <material
        name="">
        <color
          rgba="1 0.6 0 1" />
      </material>
    </visual>
    <collision>
      <origin
        xyz="0 0 0"
        rpy="0 0 0" />
      <geometry>
        <mesh
          filename="package://faraday_support/meshes/limb1_link2.STL" />
      </geometry>
    </collision>
  </link>

  <joint
    name="limb4_link3_joint"
    type="revolute">
    <origin
      xyz="0 0 0"
      rpy="-1.570796326794897 -1.011023857119764 3.141592653589793" />
    <parent
      link="limb4_link2" />
    <child
      link="limb4_link3" />
    <axis
      xyz="0 0 1" />
    <limit
      lower="-1.57"
      upper="1.57"
      effort="0"
      velocity="0" />
  </joint>

  <link
    name="limb4_link3">
    <inertial>
      <origin
        xyz="0 -101.508543691E-03 0"
        rpy="0 0 0" />
      <mass
        value="0.048981588" />
      <inertia
        ixx="283.193897053E-06"
        ixy="0"
        ixz="0"
        iyy="0.978504361E-06"
        iyz="0"
        izz="282.792129790E-06" />
    </inertial>
    <visual>
      <origin
        xyz="0 0 0"
        rpy="0 0 0" />
      <geometry>
        <mesh
          filename="package://faraday_support/meshes/limb1_link3.STL" />
      </geometry>
      <material
        name="">
        <color
          rgba="0.807843137254902 0.843137254901961 0.905882352941176 1" />
      </material>
    </visual>
    <collision>
      <origin
        xyz="0 0 0"
        rpy="0 0 0" />
      <geometry>
        <mesh
          filename="package://faraday_support/meshes/limb1_link3.STL" />
      </geometry>
    </collision>
  </link> 

  <joint
    name="limb4_link4_joint"
    type="continuous">
    <origin
      xyz="0 -246.0E-03 0"
      rpy="1.570796326794897 -1.371521614119192 0" />
    <parent
      link="limb4_link3" />
    <child
      link="limb4_link4" />
    <axis
      xyz="0 0 1" />
  </joint>

  <link
    name="limb4_link4">
    <inertial>
      <origin
        xyz="0 0 -28.989992853E-03"
        rpy="0 0 0" />
      <mass
        value="0.043557642" />
      <inertia
        ixx="16.645965669E-06"
        ixy="0"
        ixz="0"
        iyy="16.244198406E-06"
        iyz="0"
        izz="2.976607171E-06" />
    </inertial>
    <visual>
      <origin
        xyz="0 0 0"
        rpy="0 0 0" />
      <geometry>
        <mesh
          filename="package://faraday_support/meshes/limb1_link4.STL" />
      </geometry>
      <material
        name="">
        <color
          rgba="0.807843137254902 0.843137254901961 0.905882352941176 1" />
      </material>
    </visual>
    <collision>
      <origin
        xyz="0 0 0"
        rpy="0 0 0" />
      <geometry>
        <mesh
          filename="package://faraday_support/meshes/limb1_link4.STL" />
      </geometry>
    </collision>
  </link>

  <joint
    name="limb4_link5_joint"
    type="revolute">
    <origin
      xyz="0 0 0"
      rpy="1.570796326794897 0.761825746520013 0" />
    <parent
      link="limb4_link4" />
    <child
      link="limb4_link5" />
    <axis
      xyz="0 0 1" />
    <limit
      lower="-1.57"
      upper="3.14"
      effort="0"
      velocity="0" />
  </joint>

  <link
    name="limb4_link5">
    <inertial>
      <origin
        xyz="0 5.927141064E-03 0"
        rpy="0 0 0" />
      <mass
        value="0.059458429" />
      <inertia
        ixx="18.846035620E-06"
        ixy="0"
        ixz="0"
        iyy="15.857290969E-06"
        iyz="0"
        izz="8.300960836E-06" />
    </inertial>
    <visual>
      <origin
        xyz="0 0 0"
        rpy="0 0 0" />
      <geometry>
        <mesh
          filename="package://faraday_support/meshes/limb1_link5.STL" />
      </geometry>
      <material
        name="">
        <color
          rgba="1 0.6 0 1" />
      </material>
    </visual>
    <collision>
      <origin
        xyz="0 0 0"
        rpy="0 0 0" />
      <geometry>
        <mesh
          filename="package://faraday_support/meshes/limb1_link5.STL" />
      </geometry>
    </collision>
  </link>  
  

<!-- !!!!!!!!!!!!!!!!!!!!!!!!limb5!!!!!!!!!!!!!!!!!!!!!!!!!!! -->
  <joint
    name="limb5_link1_joint"
    type="prismatic">
    <origin
      xyz="-175E-03 -69E-03 -46E-03"
      rpy="-1.570796326794897 1.570796326794897 0" />
    <parent
      link="base_link" />
    <child
      link="limb5_link1" />
    <axis
      xyz="0 0 1" />
    <limit
      lower="-74.73E-03"
      upper="163.67E-03"
      effort="0"
      velocity="0" />
  </joint>

  <link
    name="limb5_link1">
    <inertial>
      <origin
        xyz="39.923426771E-03 -272.230174647E-03 -7.742022410E-03"
        rpy="0 0 0" />
      <mass
        value="3.924530231" />
      <inertia
        ixx="102738.340951455E-06"
        ixy="-1894.575417592E-06"
        ixz="417.662702993E-06"
        iyy="2619.798959665E-06"
        iyz="-3027.568909992E-06"
        izz="103747.497534297E-06" />
    </inertial>
    <visual>
      <origin
        xyz="0 0 0"
        rpy="0 0 0" />
      <geometry>
        <mesh
          filename="package://faraday_support/meshes/limb5_link1.STL" />
      </geometry>
      <material
        name="">
        <color
          rgba="0.79216 0.81961 0.93333 1" />
      </material>
    </visual>
    <collision>
      <origin
        xyz="0 0 0"
        rpy="0 0 0" />
      <geometry>
        <mesh
          filename="package://faraday_support/meshes/limb5_link1.STL" />
      </geometry>
    </collision>
  </link>

  <joint
    name="limb5_link2_joint"
    type="prismatic">
    <origin
      xyz="47.5E-03 -175E-03 0"
      rpy="1.570796326794897 -1.570796326794897 0" />
    <parent
      link="limb5_link1" />
    <child
      link="limb5_link2" />
    <axis
      xyz="0 0 1" />
    <limit
      lower="-119.2E-03"
      upper="119.2E-03"
      effort="0"
      velocity="0" />
  </joint>

  <link
    name="limb5_link2">
    <inertial>
      <origin
        xyz="30.470732749E-03 -51.432760241E-03 -0.386936280E-03"
        rpy="0 0 0" />
      <mass
        value="3.150877503" />
      <inertia
        ixx="67781.063742233E-06"
        ixy="-1958.092220321E-06"
        ixz="-0.920034342E-06"
        iyy="1174.517606162E-06"
        iyz="-145.845128068E-06"
        izz="67683.505348463E-06" />
    </inertial>
    <visual>
      <origin
        xyz="0 0 0"
        rpy="0 0 0" />
      <geometry>
        <mesh
          filename="package://faraday_support/meshes/limb5_link2.STL" />
      </geometry>
      <material
        name="">
        <color
          rgba="0.79216 0.81961 0.93333 1" />
      </material>
    </visual>
    <collision>
      <origin
        xyz="0 0 0"
        rpy="0 0 0" />
      <geometry>
        <mesh
          filename="package://faraday_support/meshes/limb5_link2.STL" />
      </geometry>
    </collision>
  </link>

  <joint
    name="limb5_link3_joint"
    type="prismatic">
    <origin
      xyz="36E-03 327.5E-03 0"
      rpy="-1.570796326794897 1.570796326794897 0" />
    <parent
      link="limb5_link2" />
    <child
      link="limb5_link3" />
    <axis
      xyz="0 0 1" />
    <limit
      lower="-111.7E-03"
      upper="188.3E-03"
      effort="0"
      velocity="0" />
  </joint>

  <link
    name="limb5_link3">
    <inertial>
      <origin
        xyz="-0.023813454E-03 -12.223769501E-03 -221.657972675E-03"
        rpy="0 0 0" />
      <mass
        value="0.404102339" />
      <inertia
        ixx="2880.706391643E-06"
        ixy="-0.059802380E-06"
        ixz="0.090166381E-06"
        iyy="2819.789309333E-06"
        iyz="-362.906597200E-06"
        izz="124.577413525E-06" />
    </inertial>
    <visual>
      <origin
        xyz="0 0 0"
        rpy="0 0 0" />
      <geometry>
        <mesh
          filename="package://faraday_support/meshes/limb5_link3.STL" />
      </geometry>
      <material
        name="">
        <color
          rgba="0.79216 0.81961 0.93333 1" />
      </material>
    </visual>
    <collision>
      <origin
        xyz="0 0 0"
        rpy="0 0 0" />
      <geometry>
        <mesh
          filename="package://faraday_support/meshes/limb5_link3.STL" />
      </geometry>
    </collision>
  </link>
  
  <joint
    name="limb5_link4_joint"
    type="revolute">
    <origin
      xyz="0 -33.0E-03 0"
      rpy="1.570796326794897 1.570796326794897 0" />
    <parent
      link="limb5_link3" />
    <child
      link="limb5_link4" />
    <axis
      xyz="0 0 1" />
    <limit
      lower="-1.75"
      upper="1.75"
      effort="0"
      velocity="0" />
  </joint>

  <link
    name="limb5_link4">
    <inertial>
      <origin
        xyz="0 0 0"
        rpy="0 0 0" />
      <mass
        value="0.017073844" />
      <inertia
        ixx="0.564166131E-06"
        ixy="0"
        ixz="0"
        iyy="0.452429837E-06"
        iyz="0"
        izz="0.452429837E-06" />
    </inertial>
    <visual>
      <origin
        xyz="0 0 0"
        rpy="0 0 0" />
      <geometry>
        <mesh
          filename="package://faraday_support/meshes/limb5_link4.STL" />
      </geometry>
      <material
        name="">
        <color
          rgba="0.80784 0.84314 0.90588 1" />
      </material>
    </visual>
    <collision>
      <origin
        xyz="0 0 0"
        rpy="0 0 0" />
      <geometry>
        <mesh
          filename="package://faraday_support/meshes/limb5_link4.STL" />
      </geometry>
    </collision>
  </link>


<!-- !!!!!!!!!!!!!!!!!!!!moveing platform!!!!!!!!!!!!!!!!!!!! -->
  <joint
    name="limb5_link5_joint"
    type="revolute">
    <origin
      xyz="0 0 0"
      rpy="1.570796326794897 0 0" />
    <parent
      link="limb5_link4" />
    <child
      link="limb5_link5" />
    <axis
      xyz="0 0 1" />
    <limit
      lower="-1.75"
      upper="1.75"
      effort="0"
      velocity="0" />
  </joint>

  <link
    name="limb5_link5">
    <inertial>
      <origin
        xyz="-64.336919702E-03 -0.001738793E-03 -0.000004541E-03"
        rpy="0 0 0" />
      <mass
        value="0.326871517" />
      <inertia
        ixx="319.891964986E-06"
        ixy="0.009746544E-06"
        ixz="-0.000079682E-06"
        iyy="292.677835661E-06"
        iyz="0.000101704E-06"
        izz="396.160131888E-06" />
    </inertial>
    <visual>
      <origin
        xyz="0 0 0"
        rpy="0 0 0" />
      <geometry>
        <mesh
          filename="package://faraday_support/meshes/move_platform.STL" />
      </geometry>
      <material
        name="">
        <color
          rgba="1 0.6 0 1" />
      </material>
    </visual>
    <collision>
      <origin
        xyz="0 0 0"
        rpy="0 0 0" />
      <geometry>
        <mesh
          filename="package://faraday_support/meshes/move_platform.STL" />
      </geometry>
    </collision>
  </link>

  <joint name="move_platform_joint" type="fixed">
    <parent link="limb5_link5"/>
    <child link="move_platform"/>
    <origin xyz="-0.076 0 0" rpy="0 -1.570796326794897 0"/>
  </joint>

  <link name="move_platform" />

  <joint
    name="motor_spindle_joint"
    type="fixed">
    <origin
      xyz="0 0 0.092"
      rpy="0 0 0" />
    <parent
      link="move_platform" />
    <child
      link="motor_spindle" />
    <axis
      xyz="0 0 1" />
  </joint>

  <link
    name="motor_spindle">
    <inertial>
      <origin
        xyz="0 0 -76.612970925E-03"
        rpy="0 0 0" />
      <mass
        value="1.126447511" />
      <inertia
        ixx="1083.714357735E-06"
        ixy="0"
        ixz="0"
        iyy="1082.159761895E-06"
        iyz="0"
        izz="267.539044505E-06" />
    </inertial>
    <visual>
      <origin
        xyz="0 0 0"
        rpy="0 0 0" />
      <geometry>
        <mesh
          filename="package://faraday_support/meshes/motor_spindle.STL" />
      </geometry>
      <material
        name="">
        <color
          rgba="0 0.6 0 1" />
      </material>
    </visual>
    <collision>
      <origin
        xyz="0 0 0"
        rpy="0 0 0" />
      <geometry>
        <mesh
          filename="package://faraday_support/meshes/motor_spindle.STL" />
      </geometry>
    </collision>
  </link>


</robot>